Workbook
Name TodayDay: RawData!$C$32
Name RevenueMonth: RawData!$C$33
Name IncentiveTarget: RawData!$C$34
Name IncentiveActual: RawData!$C$35

Sheet Dashboard
A1: 📊 Daily MA Dashboard — PCRC
A2: ="หน่วยงาน: PCRC | สัปดาห์ที่: 27–30 | ช่วงเวลา: 29 มิถุนายน – 26 กรกฎาคม 2569"
A3: ="ข้อมูล ณ วันที่: "&INDEX(RawData!C2:C29,MATCH(TodayDay-1,RawData!A2:A29,0))&" | Revenue สายธุรกิจ: ฿"&TEXT(RevenueMonth,"#,##0.00")&" | เปรียบเทียบกับ: สัปดาห์ 10–13 (มี.ค. 2569)"
A5: 📆 สะสม (29 มิถุนายน – 26 กรกฎาคม 2569) สัปดาห์ 27–30 | I5: ="📅 ล่าสุด วันที่ "&INDEX(RawData!C2:C29,MATCH(TodayDay-1,RawData!A2:A29,0))&" (สัปดาห์ "&INDEX(RawData!B2:B29,MATCH(TodayDay-1,RawData!A2:A29,0))&")"
A6: Revenue ของสายธุรกิจ | F6: =RevenueMonth | I6: Revenue ของสายธุรกิจ | N6: =INDEX(RawData!Y2:Y29,MATCH(TodayDay-1,RawData!A2:A29,0))
A7: Gross MA Actual | F7: =SUM(RawData!W2:W29) | I7: Gross MA Actual | N7: =INDEX(RawData!W2:W29,MATCH(TodayDay-1,RawData!A2:A29,0))
A8: Gross MA Target | F8: =SUM(RawData!M2:M29) | I8: Gross MA Target | N8: =INDEX(RawData!M2:M29,MATCH(TodayDay-1,RawData!A2:A29,0))
A9: Gap (Actual − Target) | F9: =F7-F8 | I9: Gap (Actual − Target) | N9: =N7-N8
A10: %MA/Revenue Actual | F10: =F7/F6 | I10: %MA/Revenue Actual | N10: =N7/N6
A11: %MA/Revenue Target | F11: =F8/F6 | I11: %MA/Revenue Target | N11: =N8/N6
A13: Incentive ประจำวัน (บาท) | D13: Gross MA รายเดือน (บาท) | G13: Daily Gross MA วันล่าสุด (บาท) | J13: %MA/Revenue วันล่าสุด | M13: %MA/Revenue สะสมเดือน
A14: =IncentiveActual | D14: =SUM(RawData!W2:W29) | G14: =INDEX(RawData!W2:W29,MATCH(TodayDay-1,RawData!A2:A29,0)) | J14: =INDEX(RawData!W2:W29,MATCH(TodayDay-1,RawData!A2:A29,0))/INDEX(RawData!Y2:Y29,MATCH(TodayDay-1,RawData!A2:A29,0)) | M14: =SUM(RawData!W2:W29)/RevenueMonth
A15: =IncentiveTarget | D15: =SUM(RawData!M2:M29) | G15: =INDEX(RawData!M2:M29,MATCH(TodayDay-1,RawData!A2:A29,0)) | J15: =INDEX(RawData!M2:M29,MATCH(TodayDay-1,RawData!A2:A29,0))/INDEX(RawData!Y2:Y29,MATCH(TodayDay-1,RawData!A2:A29,0)) | M15: =SUM(RawData!M2:M29)/RevenueMonth
A16: =IF((A14-A15)>=0,"▲ + ดีกว่า Target "&TEXT(ABS(A14-A15),"#,##0"),"▼ - แย่กว่า Target "&TEXT(ABS(A14-A15),"#,##0")) | D16: =IF((D14-D15)>=0,"▲ + ดีกว่า Target "&TEXT(ABS(D14-D15),"#,##0"),"▼ - แย่กว่า Target "&TEXT(ABS(D14-D15),"#,##0")) | G16: =IF((G14-G15)>=0,"▲ + ดีกว่า Target "&TEXT(ABS(G14-G15),"#,##0"),"▼ - แย่กว่า Target "&TEXT(ABS(G14-G15),"#,##0")) | J16: =IF((J14-J15)>=0,"▲ + ดีกว่า Target "&TEXT(ABS(J14-J15),"0.00%"),"▼ - แย่กว่า Target "&TEXT(ABS(J14-J15),"0.00%")) | M16: =IF((M14-M15)>=0,"▲ + ดีกว่า Target "&TEXT(ABS(M14-M15),"0.00%"),"▼ - แย่กว่า Target "&TEXT(ABS(M14-M15),"0.00%"))
A18: 📈 Target vs Actual %MA รายวัน | I18: 📊 Components สะสม (Target vs Actual)
A38: ="Breakdown รายสายธุรกิจ (สะสม "&RawData!C2&"–"&INDEX(RawData!C2:C29,MATCH(TodayDay-1,RawData!A2:A29,0))&")"
A39: JRTS | E39: Association Product | I39: Association Refer | M39: Reciprocation
A40: =SUMIFS(RawData!O2:O29,RawData!A2:A29,"<"&TodayDay) | E40: =SUMIFS(RawData!P2:P29,RawData!A2:A29,"<"&TodayDay) | I40: =SUMIFS(RawData!Q2:Q29,RawData!A2:A29,"<"&TodayDay) | M40: =SUMIFS(RawData!R2:R29,RawData!A2:A29,"<"&TodayDay)
A41: =SUMIFS(RawData!E2:E29,RawData!A2:A29,"<"&TodayDay) | E41: =SUMIFS(RawData!F2:F29,RawData!A2:A29,"<"&TodayDay) | I41: =SUMIFS(RawData!G2:G29,RawData!A2:A29,"<"&TodayDay) | M41: =SUMIFS(RawData!H2:H29,RawData!A2:A29,"<"&TodayDay)
A42: =IF((A40-A41)>=0,"▲ +"&TEXT(ABS(A40-A41),"#,##0.00"),"▼ "&TEXT(ABS(A40-A41),"#,##0.00")) | E42: =IF((E40-E41)>=0,"▲ +"&TEXT(ABS(E40-E41),"#,##0.00"),"▼ "&TEXT(ABS(E40-E41),"#,##0.00")) | I42: =IF((I40-I41)>=0,"▲ +"&TEXT(ABS(I40-I41),"#,##0.00"),"▼ "&TEXT(ABS(I40-I41),"#,##0.00")) | M42: =IF((M40-M41)>=0,"▲ +"&TEXT(ABS(M40-M41),"#,##0.00"),"▼ "&TEXT(ABS(M40-M41),"#,##0.00"))
A43: Shop Online 1 | E43: Shop Online 2 | I43: Project | M43: Service
A44: =SUMIFS(RawData!S2:S29,RawData!A2:A29,"<"&TodayDay) | E44: =SUMIFS(RawData!T2:T29,RawData!A2:A29,"<"&TodayDay) | I44: =SUMIFS(RawData!U2:U29,RawData!A2:A29,"<"&TodayDay) | M44: =SUMIFS(RawData!V2:V29,RawData!A2:A29,"<"&TodayDay)
A45: =SUMIFS(RawData!I2:I29,RawData!A2:A29,"<"&TodayDay) | E45: =SUMIFS(RawData!J2:J29,RawData!A2:A29,"<"&TodayDay) | I45: =SUMIFS(RawData!K2:K29,RawData!A2:A29,"<"&TodayDay) | M45: =SUMIFS(RawData!L2:L29,RawData!A2:A29,"<"&TodayDay)
A46: =IF((A44-A45)>=0,"▲ +"&TEXT(ABS(A44-A45),"#,##0.00"),"▼ "&TEXT(ABS(A44-A45),"#,##0.00")) | E46: =IF((E44-E45)>=0,"▲ +"&TEXT(ABS(E44-E45),"#,##0.00"),"▼ "&TEXT(ABS(E44-E45),"#,##0.00")) | I46: =IF((I44-I45)>=0,"▲ +"&TEXT(ABS(I44-I45),"#,##0.00"),"▼ "&TEXT(ABS(I44-I45),"#,##0.00")) | M46: =IF((M44-M45)>=0,"▲ +"&TEXT(ABS(M44-M45),"#,##0.00"),"▼ "&TEXT(ABS(M44-M45),"#,##0.00"))
A49: ตารางสรุปรายสัปดาห์
A50: สัปดาห์ | B50: ช่วงวันที่ | C50: ประเภท | D50: JRTS | E50: Association Product | F50: Association Refer | G50: Reciprocation | H50: Shop Online 1 | I50: Shop Online 2 | J50: Project | K50: Service | L50: Total | M50: %MA/Rev
A51: 27 | B51: 29 มิ.ย.–5 ก.ค. | C51: Target | D51: =SUMIFS(RawData!E2:E29,RawData!B2:B29,27) | E51: =SUMIFS(RawData!F2:F29,RawData!B2:B29,27) | F51: =SUMIFS(RawData!G2:G29,RawData!B2:B29,27) | G51: =SUMIFS(RawData!H2:H29,RawData!B2:B29,27) | H51: =SUMIFS(RawData!I2:I29,RawData!B2:B29,27) | I51: =SUMIFS(RawData!J2:J29,RawData!B2:B29,27) | J51: =SUMIFS(RawData!K2:K29,RawData!B2:B29,27) | K51: =SUMIFS(RawData!L2:L29,RawData!B2:B29,27) | L51: =SUMIFS(RawData!M2:M29,RawData!B2:B29,27) | M51: =AVERAGEIFS(RawData!N2:N29,RawData!B2:B29,27)
C52: Actual | D52: =SUMIFS(RawData!O2:O29,RawData!B2:B29,27) | E52: =SUMIFS(RawData!P2:P29,RawData!B2:B29,27) | F52: =SUMIFS(RawData!Q2:Q29,RawData!B2:B29,27) | G52: =SUMIFS(RawData!R2:R29,RawData!B2:B29,27) | H52: =SUMIFS(RawData!S2:S29,RawData!B2:B29,27) | I52: =SUMIFS(RawData!T2:T29,RawData!B2:B29,27) | J52: =SUMIFS(RawData!U2:U29,RawData!B2:B29,27) | K52: =SUMIFS(RawData!V2:V29,RawData!B2:B29,27) | L52: =SUMIFS(RawData!W2:W29,RawData!B2:B29,27) | M52: =AVERAGEIFS(RawData!X2:X29,RawData!B2:B29,27)
C53: Gap | D53: =D52-D51 | E53: =E52-E51 | F53: =F52-F51 | G53: =G52-G51 | H53: =H52-H51 | I53: =I52-I51 | J53: =J52-J51 | K53: =K52-K51 | ... M53: =M52-M51
A54: 28 | B54: 6–12 ก.ค. | C54: Target | D54: =SUMIFS(RawData!E2:E29,RawData!B2:B29,28) | E54: =SUMIFS(RawData!F2:F29,RawData!B2:B29,28) | F54: =SUMIFS(RawData!G2:G29,RawData!B2:B29,28) | G54: =SUMIFS(RawData!H2:H29,RawData!B2:B29,28) | H54: =SUMIFS(RawData!I2:I29,RawData!B2:B29,28) | I54: =SUMIFS(RawData!J2:J29,RawData!B2:B29,28) | J54: =SUMIFS(RawData!K2:K29,RawData!B2:B29,28) | K54: =SUMIFS(RawData!L2:L29,RawData!B2:B29,28) | L54: =SUMIFS(RawData!M2:M29,RawData!B2:B29,28) | M54: =AVERAGEIFS(RawData!N2:N29,RawData!B2:B29,28)
C55: Actual | D55: =SUMIFS(RawData!O2:O29,RawData!B2:B29,28) | E55: =SUMIFS(RawData!P2:P29,RawData!B2:B29,28) | F55: =SUMIFS(RawData!Q2:Q29,RawData!B2:B29,28) | G55: =SUMIFS(RawData!R2:R29,RawData!B2:B29,28) | H55: =SUMIFS(RawData!S2:S29,RawData!B2:B29,28) | I55: =SUMIFS(RawData!T2:T29,RawData!B2:B29,28) | J55: =SUMIFS(RawData!U2:U29,RawData!B2:B29,28) | K55: =SUMIFS(RawData!V2:V29,RawData!B2:B29,28) | L55: =SUMIFS(RawData!W2:W29,RawData!B2:B29,28) | M55: =AVERAGEIFS(RawData!X2:X29,RawData!B2:B29,28)
C56: Gap | D56: =D55-D54 | E56: =E55-E54 | F56: =F55-F54 | G56: =G55-G54 | H56: =H55-H54 | I56: =I55-I54 | J56: =J55-J54 | K56: =K55-K54 | ... M56: =M55-M54
A57: 29 | B57: 13–19 ก.ค. | C57: Target | D57: =SUMIFS(RawData!E2:E29,RawData!B2:B29,29) | E57: =SUMIFS(RawData!F2:F29,RawData!B2:B29,29) | F57: =SUMIFS(RawData!G2:G29,RawData!B2:B29,29) | G57: =SUMIFS(RawData!H2:H29,RawData!B2:B29,29) | H57: =SUMIFS(RawData!I2:I29,RawData!B2:B29,29) | I57: =SUMIFS(RawData!J2:J29,RawData!B2:B29,29) | J57: =SUMIFS(RawData!K2:K29,RawData!B2:B29,29) | K57: =SUMIFS(RawData!L2:L29,RawData!B2:B29,29) | L57: =SUMIFS(RawData!M2:M29,RawData!B2:B29,29) | M57: =AVERAGEIFS(RawData!N2:N29,RawData!B2:B29,29)
C58: Actual | D58: =SUMIFS(RawData!O2:O29,RawData!B2:B29,29) | E58: =SUMIFS(RawData!P2:P29,RawData!B2:B29,29) | F58: =SUMIFS(RawData!Q2:Q29,RawData!B2:B29,29) | G58: =SUMIFS(RawData!R2:R29,RawData!B2:B29,29) | H58: =SUMIFS(RawData!S2:S29,RawData!B2:B29,29) | I58: =SUMIFS(RawData!T2:T29,RawData!B2:B29,29) | J58: =SUMIFS(RawData!U2:U29,RawData!B2:B29,29) | K58: =SUMIFS(RawData!V2:V29,RawData!B2:B29,29) | L58: =SUMIFS(RawData!W2:W29,RawData!B2:B29,29) | M58: =AVERAGEIFS(RawData!X2:X29,RawData!B2:B29,29)
C59: Gap | D59: =D58-D57 | E59: =E58-E57 | F59: =F58-F57 | G59: =G58-G57 | H59: =H58-H57 | I59: =I58-I57 | J59: =J58-J57 | K59: =K58-K57 | ... M59: =M58-M57
A60: 30 | B60: 20–26 ก.ค. | C60: Target | D60: =SUMIFS(RawData!E2:E29,RawData!B2:B29,30) | E60: =SUMIFS(RawData!F2:F29,RawData!B2:B29,30) | F60: =SUMIFS(RawData!G2:G29,RawData!B2:B29,30) | G60: =SUMIFS(RawData!H2:H29,RawData!B2:B29,30) | H60: =SUMIFS(RawData!I2:I29,RawData!B2:B29,30) | I60: =SUMIFS(RawData!J2:J29,RawData!B2:B29,30) | J60: =SUMIFS(RawData!K2:K29,RawData!B2:B29,30) | K60: =SUMIFS(RawData!L2:L29,RawData!B2:B29,30) | L60: =SUMIFS(RawData!M2:M29,RawData!B2:B29,30) | M60: =AVERAGEIFS(RawData!N2:N29,RawData!B2:B29,30)
C61: Actual | D61: =SUMIFS(RawData!O2:O29,RawData!B2:B29,30) | E61: =SUMIFS(RawData!P2:P29,RawData!B2:B29,30) | F61: =SUMIFS(RawData!Q2:Q29,RawData!B2:B29,30) | G61: =SUMIFS(RawData!R2:R29,RawData!B2:B29,30) | H61: =SUMIFS(RawData!S2:S29,RawData!B2:B29,30) | I61: =SUMIFS(RawData!T2:T29,RawData!B2:B29,30) | J61: =SUMIFS(RawData!U2:U29,RawData!B2:B29,30) | K61: =SUMIFS(RawData!V2:V29,RawData!B2:B29,30) | L61: =SUMIFS(RawData!W2:W29,RawData!B2:B29,30) | M61: =AVERAGEIFS(RawData!X2:X29,RawData!B2:B29,30)
C62: Gap | D62: =D61-D60 | E62: =E61-E60 | F62: =F61-F60 | G62: =G61-G60 | H62: =H61-H60 | I62: =I61-I60 | J62: =J61-J60 | K62: =K61-K60 | ... M62: =M61-M60
A65: เปรียบเทียบกับสัปดาห์อ้างอิง (สัปดาห์ 10–13 (มี.ค. 2569))
A66: รายการ | B66: ช่วงเวลา | C66: JRTS | D66: Association Product | E66: Association Refer | F66: Reciprocation | G66: Shop Online 1 | H66: Shop Online 2 | I66: Project | J66: Service | K66: Total | L66: %MA/Rev
...

Sheet DailyMA
A1: 📅 DailyMA — รายวัน สัปดาห์ 27–30 (29 มิถุนายน – 26 กรกฎาคม 2569)
A2: ="ช่วง: 29 มิถุนายน – 26 กรกฎาคม 2569 | สัปดาห์: 27–30 | Revenue: ฿"&TEXT(RevenueMonth,"#,##0.00")
A4: JRTS สะสม (Actual) | D4: Shop Online สะสม (Actual) | G4: Total MA สะสม (Actual) | J4: %MA/Rev สะสม
A5: =SUMIFS(RawData!O2:O29,RawData!A2:A29,"<"&TodayDay) | D5: =SUMIFS(RawData!S2:S29,RawData!A2:A29,"<"&TodayDay)+SUMIFS(RawData!T2:T29,RawData!A2:A29,"<"&TodayDay) | G5: =SUMIFS(RawData!W2:W29,RawData!A2:A29,"<"&TodayDay) | J5: =SUMIFS(RawData!W2:W29,RawData!A2:A29,"<"&TodayDay)/RevenueMonth
A6: =SUM(RawData!E2:E29) | D6: =SUM(RawData!I2:I29)+SUM(RawData!J2:J29) | G6: =SUM(RawData!M2:M29) | J6: =SUM(RawData!M2:M29)/RevenueMonth
A8: ตารางรายวัน Target / Actual / Gap
A9: สัปดาห์ | B9: วันที่ | C9: ประเภท | D9: JRTS | E9: Association Product | F9: Association Refer | G9: Reciprocation | H9: Shop Online 1 | I9: Shop Online 2 | J9: Project | K9: Service | L9: Total | M9: %MA/Rev
A10: 27 | B10: 29 มิ.ย. 2569 | C10: Target | D10: =RawData!E2 | E10: =RawData!F2 | F10: =RawData!G2 | G10: =RawData!H2 | H10: =RawData!I2 | I10: =RawData!J2 | J10: =RawData!K2 | K10: =RawData!L2 | ... M10: =RawData!N2
C11: Actual | D11: =IF(RawData!A2<TodayDay,RawData!O2,"") | E11: =IF(RawData!A2<TodayDay,RawData!P2,"") | F11: =IF(RawData!A2<TodayDay,RawData!Q2,"") | G11: =IF(RawData!A2<TodayDay,RawData!R2,"") | H11: =IF(RawData!A2<TodayDay,RawData!S2,"") | I11: =IF(RawData!A2<TodayDay,RawData!T2,"") | J11: =IF(RawData!A2<TodayDay,RawData!U2,"") | K11: =IF(RawData!A2<TodayDay,RawData!V2,"") | L11: =IF(RawData!A2<TodayDay,RawData!W2,"") | M11: =IF(RawData!A2<TodayDay,RawData!X2,"")
C12: Gap | D12: =IF(RawData!A2<TodayDay,D11-D10,"") | E12: =IF(RawData!A2<TodayDay,E11-E10,"") | F12: =IF(RawData!A2<TodayDay,F11-F10,"") | G12: =IF(RawData!A2<TodayDay,G11-G10,"") | H12: =IF(RawData!A2<TodayDay,H11-H10,"") | I12: =IF(RawData!A2<TodayDay,I11-I10,"") | J12: =IF(RawData!A2<TodayDay,J11-J10,"") | K12: =IF(RawData!A2<TodayDay,K11-K10,"") | L12: =IF(RawData!A2<TodayDay,L11-L10,"") | M12: =IF(RawData!A2<TodayDay,M11-M10,"")
B13: 30 มิ.ย. 2569 | C13: Target | D13: =RawData!E3 | E13: =RawData!F3 | F13: =RawData!G3 | G13: =RawData!H3 | H13: =RawData!I3 | I13: =RawData!J3 | J13: =RawData!K3 | K13: =RawData!L3 | ... M13: =RawData!N3
C14: Actual | D14: =IF(RawData!A3<TodayDay,RawData!O3,"") | E14: =IF(RawData!A3<TodayDay,RawData!P3,"") | F14: =IF(RawData!A3<TodayDay,RawData!Q3,"") | G14: =IF(RawData!A3<TodayDay,RawData!R3,"") | H14: =IF(RawData!A3<TodayDay,RawData!S3,"") | I14: =IF(RawData!A3<TodayDay,RawData!T3,"") | J14: =IF(RawData!A3<TodayDay,RawData!U3,"") | K14: =IF(RawData!A3<TodayDay,RawData!V3,"") | L14: =IF(RawData!A3<TodayDay,RawData!W3,"") | M14: =IF(RawData!A3<TodayDay,RawData!X3,"")
C15: Gap | D15: =IF(RawData!A3<TodayDay,D14-D13,"") | E15: =IF(RawData!A3<TodayDay,E14-E13,"") | F15: =IF(RawData!A3<TodayDay,F14-F13,"") | G15: =IF(RawData!A3<TodayDay,G14-G13,"") | H15: =IF(RawData!A3<TodayDay,H14-H13,"") | I15: =IF(RawData!A3<TodayDay,I14-I13,"") | J15: =IF(RawData!A3<TodayDay,J14-J13,"") | K15: =IF(RawData!A3<TodayDay,K14-K13,"") | L15: =IF(RawData!A3<TodayDay,L14-L13,"") | M15: =IF(RawData!A3<TodayDay,M14-M13,"")
B16: 1 ก.ค. 2569 | C16: Target | D16: =RawData!E4 | E16: =RawData!F4 | F16: =RawData!G4 | G16: =RawData!H4 | H16: =RawData!I4 | I16: =RawData!J4 | J16: =RawData!K4 | K16: =RawData!L4 | ... M16: =RawData!N4
C17: Actual | D17: =IF(RawData!A4<TodayDay,RawData!O4,"") | E17: =IF(RawData!A4<TodayDay,RawData!P4,"") | F17: =IF(RawData!A4<TodayDay,RawData!Q4,"") | G17: =IF(RawData!A4<TodayDay,RawData!R4,"") | H17: =IF(RawData!A4<TodayDay,RawData!S4,"") | I17: =IF(RawData!A4<TodayDay,RawData!T4,"") | J17: =IF(RawData!A4<TodayDay,RawData!U4,"") | K17: =IF(RawData!A4<TodayDay,RawData!V4,"") | L17: =IF(RawData!A4<TodayDay,RawData!W4,"") | M17: =IF(RawData!A4<TodayDay,RawData!X4,"")
C18: Gap | D18: =IF(RawData!A4<TodayDay,D17-D16,"") | E18: =IF(RawData!A4<TodayDay,E17-E16,"") | F18: =IF(RawData!A4<TodayDay,F17-F16,"") | G18: =IF(RawData!A4<TodayDay,G17-G16,"") | H18: =IF(RawData!A4<TodayDay,H17-H16,"") | I18: =IF(RawData!A4<TodayDay,I17-I16,"") | J18: =IF(RawData!A4<TodayDay,J17-J16,"") | K18: =IF(RawData!A4<TodayDay,K17-K16,"") | L18: =IF(RawData!A4<TodayDay,L17-L16,"") | M18: =IF(RawData!A4<TodayDay,M17-M16,"")
B19: 2 ก.ค. 2569 | C19: Target | D19: =RawData!E5 | E19: =RawData!F5 | F19: =RawData!G5 | G19: =RawData!H5 | H19: =RawData!I5 | I19: =RawData!J5 | J19: =RawData!K5 | K19: =RawData!L5 | ... M19: =RawData!N5
C20: Actual | D20: =IF(RawData!A5<TodayDay,RawData!O5,"") | E20: =IF(RawData!A5<TodayDay,RawData!P5,"") | F20: =IF(RawData!A5<TodayDay,RawData!Q5,"") | G20: =IF(RawData!A5<TodayDay,RawData!R5,"") | H20: =IF(RawData!A5<TodayDay,RawData!S5,"") | I20: =IF(RawData!A5<TodayDay,RawData!T5,"") | J20: =IF(RawData!A5<TodayDay,RawData!U5,"") | K20: =IF(RawData!A5<TodayDay,RawData!V5,"") | L20: =IF(RawData!A5<TodayDay,RawData!W5,"") | M20: =IF(RawData!A5<TodayDay,RawData!X5,"")
C21: Gap | D21: =IF(RawData!A5<TodayDay,D20-D19,"") | E21: =IF(RawData!A5<TodayDay,E20-E19,"") | F21: =IF(RawData!A5<TodayDay,F20-F19,"") | G21: =IF(RawData!A5<TodayDay,G20-G19,"") | H21: =IF(RawData!A5<TodayDay,H20-H19,"") | I21: =IF(RawData!A5<TodayDay,I20-I19,"") | J21: =IF(RawData!A5<TodayDay,J20-J19,"") | K21: =IF(RawData!A5<TodayDay,K20-K19,"") | L21: =IF(RawData!A5<TodayDay,L20-L19,"") | M21: =IF(RawData!A5<TodayDay,M20-M19,"")
B22: 3 ก.ค. 2569 | C22: Target | D22: =RawData!E6 | E22: =RawData!F6 | F22: =RawData!G6 | G22: =RawData!H6 | H22: =RawData!I6 | I22: =RawData!J6 | J22: =RawData!K6 | K22: =RawData!L6 | ... M22: =RawData!N6
C23: Actual | D23: =IF(RawData!A6<TodayDay,RawData!O6,"") | E23: =IF(RawData!A6<TodayDay,RawData!P6,"") | F23: =IF(RawData!A6<TodayDay,RawData!Q6,"") | G23: =IF(RawData!A6<TodayDay,RawData!R6,"") | H23: =IF(RawData!A6<TodayDay,RawData!S6,"") | I23: =IF(RawData!A6<TodayDay,RawData!T6,"") | J23: =IF(RawData!A6<TodayDay,RawData!U6,"") | K23: =IF(RawData!A6<TodayDay,RawData!V6,"") | L23: =IF(RawData!A6<TodayDay,RawData!W6,"") | M23: =IF(RawData!A6<TodayDay,RawData!X6,"")
C24: Gap | D24: =IF(RawData!A6<TodayDay,D23-D22,"") | E24: =IF(RawData!A6<TodayDay,E23-E22,"") | F24: =IF(RawData!A6<TodayDay,F23-F22,"") | G24: =IF(RawData!A6<TodayDay,G23-G22,"") | H24: =IF(RawData!A6<TodayDay,H23-H22,"") | I24: =IF(RawData!A6<TodayDay,I23-I22,"") | J24: =IF(RawData!A6<TodayDay,J23-J22,"") | K24: =IF(RawData!A6<TodayDay,K23-K22,"") | L24: =IF(RawData!A6<TodayDay,L23-L22,"") | M24: =IF(RawData!A6<TodayDay,M23-M22,"")
B25: 4 ก.ค. 2569 (วันหยุด) | C25: Target | D25: =RawData!E7 | E25: =RawData!F7 | F25: =RawData!G7 | G25: =RawData!H7 | H25: =RawData!I7 | I25: =RawData!J7 | J25: =RawData!K7 | K25: =RawData!L7 | ... M25: =RawData!N7
C26: Actual | D26: =IF(RawData!A7<TodayDay,RawData!O7,"") | E26: =IF(RawData!A7<TodayDay,RawData!P7,"") | F26: =IF(RawData!A7<TodayDay,RawData!Q7,"") | G26: =IF(RawData!A7<TodayDay,RawData!R7,"") | H26: =IF(RawData!A7<TodayDay,RawData!S7,"") | I26: =IF(RawData!A7<TodayDay,RawData!T7,"") | J26: =IF(RawData!A7<TodayDay,RawData!U7,"") | K26: =IF(RawData!A7<TodayDay,RawData!V7,"") | L26: =IF(RawData!A7<TodayDay,RawData!W7,"") | M26: =IF(RawData!A7<TodayDay,RawData!X7,"")
C27: Gap | D27: =IF(RawData!A7<TodayDay,D26-D25,"") | E27: =IF(RawData!A7<TodayDay,E26-E25,"") | F27: =IF(RawData!A7<TodayDay,F26-F25,"") | G27: =IF(RawData!A7<TodayDay,G26-G25,"") | H27: =IF(RawData!A7<TodayDay,H26-H25,"") | I27: =IF(RawData!A7<TodayDay,I26-I25,"") | J27: =IF(RawData!A7<TodayDay,J26-J25,"") | K27: =IF(RawData!A7<TodayDay,K26-K25,"") | L27: =IF(RawData!A7<TodayDay,L26-L25,"") | M27: =IF(RawData!A7<TodayDay,M26-M25,"")
B28: 5 ก.ค. 2569 (วันหยุด) | C28: Target | D28: =RawData!E8 | E28: =RawData!F8 | F28: =RawData!G8 | G28: =RawData!H8 | H28: =RawData!I8 | I28: =RawData!J8 | J28: =RawData!K8 | K28: =RawData!L8 | ... M28: =RawData!N8
C29: Actual | D29: =IF(RawData!A8<TodayDay,RawData!O8,"") | E29: =IF(RawData!A8<TodayDay,RawData!P8,"") | F29: =IF(RawData!A8<TodayDay,RawData!Q8,"") | G29: =IF(RawData!A8<TodayDay,RawData!R8,"") | H29: =IF(RawData!A8<TodayDay,RawData!S8,"") | I29: =IF(RawData!A8<TodayDay,RawData!T8,"") | J29: =IF(RawData!A8<TodayDay,RawData!U8,"") | K29: =IF(RawData!A8<TodayDay,RawData!V8,"") | L29: =IF(RawData!A8<TodayDay,RawData!W8,"") | M29: =IF(RawData!A8<TodayDay,RawData!X8,"")
C30: Gap | D30: =IF(RawData!A8<TodayDay,D29-D28,"") | E30: =IF(RawData!A8<TodayDay,E29-E28,"") | F30: =IF(RawData!A8<TodayDay,F29-F28,"") | G30: =IF(RawData!A8<TodayDay,G29-G28,"") | H30: =IF(RawData!A8<TodayDay,H29-H28,"") | I30: =IF(RawData!A8<TodayDay,I29-I28,"") | J30: =IF(RawData!A8<TodayDay,J29-J28,"") | K30: =IF(RawData!A8<TodayDay,K29-K28,"") | L30: =IF(RawData!A8<TodayDay,L29-L28,"") | M30: =IF(RawData!A8<TodayDay,M29-M28,"")
A31: 28 | B31: 6 ก.ค. 2569 | C31: Target | D31: =RawData!E9 | E31: =RawData!F9 | F31: =RawData!G9 | G31: =RawData!H9 | H31: =RawData!I9 | I31: =RawData!J9 | J31: =RawData!K9 | K31: =RawData!L9 | ... M31: =RawData!N9
C32: Actual | D32: =IF(RawData!A9<TodayDay,RawData!O9,"") | E32: =IF(RawData!A9<TodayDay,RawData!P9,"") | F32: =IF(RawData!A9<TodayDay,RawData!Q9,"") | G32: =IF(RawData!A9<TodayDay,RawData!R9,"") | H32: =IF(RawData!A9<TodayDay,RawData!S9,"") | I32: =IF(RawData!A9<TodayDay,RawData!T9,"") | J32: =IF(RawData!A9<TodayDay,RawData!U9,"") | K32: =IF(RawData!A9<TodayDay,RawData!V9,"") | L32: =IF(RawData!A9<TodayDay,RawData!W9,"") | M32: =IF(RawData!A9<TodayDay,RawData!X9,"")
C33: Gap | D33: =IF(RawData!A9<TodayDay,D32-D31,"") | E33: =IF(RawData!A9<TodayDay,E32-E31,"") | F33: =IF(RawData!A9<TodayDay,F32-F31,"") | G33: =IF(RawData!A9<TodayDay,G32-G31,"") | H33: =IF(RawData!A9<TodayDay,H32-H31,"") | I33: =IF(RawData!A9<TodayDay,I32-I31,"") | J33: =IF(RawData!A9<TodayDay,J32-J31,"") | K33: =IF(RawData!A9<TodayDay,K32-K31,"") | L33: =IF(RawData!A9<TodayDay,L32-L31,"") | M33: =IF(RawData!A9<TodayDay,M32-M31,"")
B34: 7 ก.ค. 2569 | C34: Target | D34: =RawData!E10 | E34: =RawData!F10 | F34: =RawData!G10 | G34: =RawData!H10 | H34: =RawData!I10 | I34: =RawData!J10 | J34: =RawData!K10 | K34: =RawData!L10 | ... M34: =RawData!N10
C35: Actual | D35: =IF(RawData!A10<TodayDay,RawData!O10,"") | E35: =IF(RawData!A10<TodayDay,RawData!P10,"") | F35: =IF(RawData!A10<TodayDay,RawData!Q10,"") | G35: =IF(RawData!A10<TodayDay,RawData!R10,"") | H35: =IF(RawData!A10<TodayDay,RawData!S10,"") | I35: =IF(RawData!A10<TodayDay,RawData!T10,"") | J35: =IF(RawData!A10<TodayDay,RawData!U10,"") | K35: =IF(RawData!A10<TodayDay,RawData!V10,"") | L35: =IF(RawData!A10<TodayDay,RawData!W10,"") | M35: =IF(RawData!A10<TodayDay,RawData!X10,"")
C36: Gap | D36: =IF(RawData!A10<TodayDay,D35-D34,"") | E36: =IF(RawData!A10<TodayDay,E35-E34,"") | F36: =IF(RawData!A10<TodayDay,F35-F34,"") | G36: =IF(RawData!A10<TodayDay,G35-G34,"") | H36: =IF(RawData!A10<TodayDay,H35-H34,"") | I36: =IF(RawData!A10<TodayDay,I35-I34,"") | J36: =IF(RawData!A10<TodayDay,J35-J34,"") | K36: =IF(RawData!A10<TodayDay,K35-K34,"") | L36: =IF(RawData!A10<TodayDay,L35-L34,"") | M36: =IF(RawData!A10<TodayDay,M35-M34,"")
B37: 8 ก.ค. 2569 | C37: Target | D37: =RawData!E11 | E37: =RawData!F11 | F37: =RawData!G11 | G37: =RawData!H11 | H37: =RawData!I11 | I37: =RawData!J11 | J37: =RawData!K11 | K37: =RawData!L11 | ... M37: =RawData!N11
C38: Actual | D38: =IF(RawData!A11<TodayDay,RawData!O11,"") | E38: =IF(RawData!A11<TodayDay,RawData!P11,"") | F38: =IF(RawData!A11<TodayDay,RawData!Q11,"") | G38: =IF(RawData!A11<TodayDay,RawData!R11,"") | H38: =IF(RawData!A11<TodayDay,RawData!S11,"") | I38: =IF(RawData!A11<TodayDay,RawData!T11,"") | J38: =IF(RawData!A11<TodayDay,RawData!U11,"") | K38: =IF(RawData!A11<TodayDay,RawData!V11,"") | L38: =IF(RawData!A11<TodayDay,RawData!W11,"") | M38: =IF(RawData!A11<TodayDay,RawData!X11,"")
C39: Gap | D39: =IF(RawData!A11<TodayDay,D38-D37,"") | E39: =IF(RawData!A11<TodayDay,E38-E37,"") | F39: =IF(RawData!A11<TodayDay,F38-F37,"") | G39: =IF(RawData!A11<TodayDay,G38-G37,"") | H39: =IF(RawData!A11<TodayDay,H38-H37,"") | I39: =IF(RawData!A11<TodayDay,I38-I37,"") | J39: =IF(RawData!A11<TodayDay,J38-J37,"") | K39: =IF(RawData!A11<TodayDay,K38-K37,"") | L39: =IF(RawData!A11<TodayDay,L38-L37,"") | M39: =IF(RawData!A11<TodayDay,M38-M37,"")
B40: 9 ก.ค. 2569 | C40: Target | D40: =RawData!E12 | E40: =RawData!F12 | F40: =RawData!G12 | G40: =RawData!H12 | H40: =RawData!I12 | I40: =RawData!J12 | J40: =RawData!K12 | K40: =RawData!L12 | ... M40: =RawData!N12
C41: Actual | D41: =IF(RawData!A12<TodayDay,RawData!O12,"") | E41: =IF(RawData!A12<TodayDay,RawData!P12,"") | F41: =IF(RawData!A12<TodayDay,RawData!Q12,"") | G41: =IF(RawData!A12<TodayDay,RawData!R12,"") | H41: =IF(RawData!A12<TodayDay,RawData!S12,"") | I41: =IF(RawData!A12<TodayDay,RawData!T12,"") | J41: =IF(RawData!A12<TodayDay,RawData!U12,"") | K41: =IF(RawData!A12<TodayDay,RawData!V12,"") | L41: =IF(RawData!A12<TodayDay,RawData!W12,"") | M41: =IF(RawData!A12<TodayDay,RawData!X12,"")
C42: Gap | D42: =IF(RawData!A12<TodayDay,D41-D40,"") | E42: =IF(RawData!A12<TodayDay,E41-E40,"") | F42: =IF(RawData!A12<TodayDay,F41-F40,"") | G42: =IF(RawData!A12<TodayDay,G41-G40,"") | H42: =IF(RawData!A12<TodayDay,H41-H40,"") | I42: =IF(RawData!A12<TodayDay,I41-I40,"") | J42: =IF(RawData!A12<TodayDay,J41-J40,"") | K42: =IF(RawData!A12<TodayDay,K41-K40,"") | L42: =IF(RawData!A12<TodayDay,L41-L40,"") | M42: =IF(RawData!A12<TodayDay,M41-M40,"")
...

Sheet RawData
A1: dayNum | B1: week | C1: date | D1: holiday | E1: Target JRTS | F1: Target Asso.Product | G1: Target Asso.Refer | H1: Target Reciprocation | I1: Target Shop Online 1 | J1: Target Shop Online 2 | K1: Target Project | L1: Target Service | M1: target_total | N1: Target %MA | O1: Actual JRTS | P1: Actual Asso.Product | Q1: Actual Asso.Refer | R1: Actual Reciprocation | S1: Actual Shop Online 1 | T1: Actual Shop Online 2 | U1: Actual Project | V1: Actual Service | W1: actual_total | X1: Actual %MA | Y1: daily_revenue
A2: 1 | B2: 27 | C2: 29 มิ.ย. 2569 | D2: FALSE | E2: -24273.865 | F2: 76.79918 | G2: 3.8461538 | H2: 6.7041166 | I2: 4.7485969 | J2: 6.1985836 | K2: 0 | L2: 0 | M2: =SUM(E2:L2) | N2: -0.1141962 | O2: -20851.79 | P2: 0 | Q2: 0 | R2: 0 | S2: 0 | T2: 466.75 | U2: 0 | V2: 0 | W2: =SUM(O2:V2) | X2: -0.096291184
A3: 2 | B3: 27 | C3: 30 มิ.ย. 2569 | D3: FALSE | E3: -24273.865 | F3: 76.79918 | G3: 3.8461538 | H3: 6.7041166 | I3: 4.7485969 | J3: 6.1985836 | K3: 0 | L3: 0 | M3: =SUM(E3:L3) | N3: -0.1141962 | O3: -24862.39 | P3: 0 | Q3: 0 | R3: 0 | S3: 0 | T3: 941.23 | U3: 0 | V3: 0 | W3: =SUM(O3:V3) | X3: -0.11299447
A4: 3 | B4: 27 | C4: 1 ก.ค. 2569 | D4: FALSE | E4: -24273.865 | F4: 76.79918 | G4: 3.8461538 | H4: 6.7041166 | I4: 4.7485969 | J4: 6.1985836 | K4: 0 | L4: 0 | M4: =SUM(E4:L4) | N4: -0.1141962 | O4: -20035.23 | P4: 0 | Q4: 0 | R4: 0 | S4: 0 | T4: 60.37 | U4: 0 | V4: 0 | W4: =SUM(O4:V4) | X4: -0.094353649
A5: 4 | B5: 27 | C5: 2 ก.ค. 2569 | D5: FALSE | E5: -24273.865 | F5: 76.79918 | G5: 3.8461538 | H5: 6.7041166 | I5: 4.7485969 | J5: 6.1985836 | K5: 0 | L5: 0 | M5: =SUM(E5:L5) | N5: -0.1141962 | O5: -26264.32 | P5: 0 | Q5: 0 | R5: 0 | S5: 0 | T5: 216.3 | U5: 0 | V5: 0 | W5: =SUM(O5:V5) | X5: -0.12304095
A6: 5 | B6: 27 | C6: 3 ก.ค. 2569 | D6: FALSE | E6: -24273.865 | F6: 76.79918 | G6: 3.8461538 | H6: 6.7041166 | I6: 4.7485969 | J6: 6.1985836 | K6: 0 | L6: 0 | M6: =SUM(E6:L6) | N6: -0.1141962 | O6: -22096.89 | P6: 0 | Q6: 0 | R6: 0 | S6: 0 | T6: 37.558 | U6: 0 | V6: 0 | W6: =SUM(O6:V6) | X6: -0.1041999
A7: 6 | B7: 27 | C7: 4 ก.ค. 2569 | D7: TRUE | E7: 0 | F7: 76.79918 | G7: 0 | H7: 0 | I7: 4.7485969 | J7: 6.1985836 | K7: 0 | L7: 0 | M7: =SUM(E7:L7) | N7: 0.00041448047 | O7: 0 | P7: 0 | Q7: 0 | R7: 0 | S7: 0 | T7: 0 | U7: 0 | V7: 0 | W7: =SUM(O7:V7) | X7: 0
A8: 7 | B8: 27 | C8: 5 ก.ค. 2569 | D8: TRUE | E8: 0 | F8: 76.79918 | G8: 0 | H8: 0 | I8: 4.7485969 | J8: 6.1985836 | K8: 0 | L8: 0 | M8: =SUM(E8:L8) | N8: 0.00041448047 | O8: 0 | P8: 0 | Q8: 0 | R8: 0 | S8: 0 | T8: 0 | U8: 0 | V8: 0 | W8: =SUM(O8:V8) | X8: 0
A9: 8 | B9: 28 | C9: 6 ก.ค. 2569 | D9: FALSE | E9: -24273.865 | F9: 76.79918 | G9: 3.8461538 | H9: 6.7041166 | I9: 4.7485969 | J9: 6.1985836 | K9: 0 | L9: 0 | M9: =SUM(E9:L9) | N9: -0.1141962 | O9: -20115.58 | P9: 0 | Q9: 0 | R9: 0 | S9: 0 | T9: 1280.26 | U9: 0 | V9: 0 | W9: =SUM(O9:V9) | X9: -0.088970895
A10: 9 | B10: 28 | C10: 7 ก.ค. 2569 | D10: FALSE | E10: -24273.865 | F10: 76.79918 | G10: 3.8461538 | H10: 6.7041166 | I10: 4.7485969 | J10: 6.1985836 | K10: 0 | L10: 0 | M10: =SUM(E10:L10) | N10: -0.1141962 | O10: -20144.4 | P10: 0 | Q10: 0 | R10: 0 | S10: 510.46 | T10: 0 | U10: 0 | V10: 0 | W10: =SUM(O10:V10) | X10: -0.092743273
A11: 10 | B11: 28 | C11: 8 ก.ค. 2569 | D11: FALSE | E11: -24273.865 | F11: 76.79918 | G11: 3.8461538 | H11: 6.7041166 | I11: 4.7485969 | J11: 6.1985836 | K11: 0 | L11: 0 | M11: =SUM(E11:L11) | N11: -0.1141962 | O11: -20742.5 | P11: 0 | Q11: 0 | R11: 0 | S11: 0 | T11: 162.43 | U11: 0 | V11: 0 | W11: =SUM(O11:V11) | X11: -0.097212431 | Y11: 211702.04
A12: 11 | B12: 28 | C12: 9 ก.ค. 2569 | D12: FALSE | E12: -24273.865 | F12: 76.79918 | G12: 3.8461538 | H12: 6.7041166 | I12: 4.7485969 | J12: 6.1985836 | K12: 0 | L12: 0 | M12: =SUM(E12:L12) | N12: -0.1141962 | O12: 0 | P12: 0 | Q12: 0 | R12: 0 | S12: 0 | T12: 0 | U12: 0 | V12: 0 | W12: =SUM(O12:V12) | X12: 0
A13: 12 | B13: 28 | C13: 10 ก.ค. 2569 | D13: FALSE | E13: -24273.865 | F13: 76.79918 | G13: 3.8461538 | H13: 6.7041166 | I13: 4.7485969 | J13: 6.1985836 | K13: 0 | L13: 0 | M13: =SUM(E13:L13) | N13: -0.1141962 | O13: 0 | P13: 0 | Q13: 0 | R13: 0 | S13: 0 | T13: 0 | U13: 0 | V13: 0 | W13: =SUM(O13:V13) | X13: 0
A14: 13 | B14: 28 | C14: 11 ก.ค. 2569 | D14: TRUE | E14: 0 | F14: 76.79918 | G14: 0 | H14: 0 | I14: 4.7485969 | J14: 6.1985836 | K14: 0 | L14: 0 | M14: =SUM(E14:L14) | N14: 0.00041448047 | O14: 0 | P14: 0 | Q14: 0 | R14: 0 | S14: 0 | T14: 0 | U14: 0 | V14: 0 | W14: =SUM(O14:V14) | X14: 0
A15: 14 | B15: 28 | C15: 12 ก.ค. 2569 | D15: TRUE | E15: 0 | F15: 76.79918 | G15: 0 | H15: 0 | I15: 4.7485969 | J15: 6.1985836 | K15: 0 | L15: 0 | M15: =SUM(E15:L15) | N15: 0.00041448047 | O15: 0 | P15: 0 | Q15: 0 | R15: 0 | S15: 0 | T15: 0 | U15: 0 | V15: 0 | W15: =SUM(O15:V15) | X15: 0
A16: 15 | B16: 29 | C16: 13 ก.ค. 2569 | D16: FALSE | E16: -24273.865 | F16: 76.79918 | G16: 3.8461538 | H16: 6.7041166 | I16: 4.7485969 | J16: 6.1985836 | K16: 0 | L16: 0 | M16: =SUM(E16:L16) | N16: -0.1141962 | O16: 0 | P16: 0 | Q16: 0 | R16: 0 | S16: 0 | T16: 0 | U16: 0 | V16: 0 | W16: =SUM(O16:V16) | X16: 0
A17: 16 | B17: 29 | C17: 14 ก.ค. 2569 | D17: FALSE | E17: -24273.865 | F17: 76.79918 | G17: 3.8461538 | H17: 6.7041166 | I17: 4.7485969 | J17: 6.1985836 | K17: 0 | L17: 0 | M17: =SUM(E17:L17) | N17: -0.1141962 | O17: 0 | P17: 0 | Q17: 0 | R17: 0 | S17: 0 | T17: 0 | U17: 0 | V17: 0 | W17: =SUM(O17:V17) | X17: 0
A18: 17 | B18: 29 | C18: 15 ก.ค. 2569 | D18: FALSE | E18: -24273.865 | F18: 76.79918 | G18: 3.8461538 | H18: 6.7041166 | I18: 4.7485969 | J18: 6.1985836 | K18: 0 | L18: 0 | M18: =SUM(E18:L18) | N18: -0.1141962 | O18: 0 | P18: 0 | Q18: 0 | R18: 0 | S18: 0 | T18: 0 | U18: 0 | V18: 0 | W18: =SUM(O18:V18) | X18: 0
A19: 18 | B19: 29 | C19: 16 ก.ค. 2569 | D19: FALSE | E19: -24273.865 | F19: 76.79918 | G19: 3.8461538 | H19: 6.7041166 | I19: 4.7485969 | J19: 6.1985836 | K19: 0 | L19: 0 | M19: =SUM(E19:L19) | N19: -0.1141962 | O19: 0 | P19: 0 | Q19: 0 | R19: 0 | S19: 0 | T19: 0 | U19: 0 | V19: 0 | W19: =SUM(O19:V19) | X19: 0
A20: 19 | B20: 29 | C20: 17 ก.ค. 2569 | D20: FALSE | E20: -24273.865 | F20: 76.79918 | G20: 3.8461538 | H20: 6.7041166 | I20: 4.7485969 | J20: 6.1985836 | K20: 0 | L20: 0 | M20: =SUM(E20:L20) | N20: -0.1141962 | O20: 0 | P20: 0 | Q20: 0 | R20: 0 | S20: 0 | T20: 0 | U20: 0 | V20: 0 | W20: =SUM(O20:V20) | X20: 0
A21: 20 | B21: 29 | C21: 18 ก.ค. 2569 | D21: TRUE | E21: 0 | F21: 76.79918 | G21: 0 | H21: 0 | I21: 4.7485969 | J21: 6.1985836 | K21: 0 | L21: 0 | M21: =SUM(E21:L21) | N21: 0.00041448047 | O21: 0 | P21: 0 | Q21: 0 | R21: 0 | S21: 0 | T21: 0 | U21: 0 | V21: 0 | W21: =SUM(O21:V21) | X21: 0
A22: 21 | B22: 29 | C22: 19 ก.ค. 2569 | D22: TRUE | E22: 0 | F22: 76.79918 | G22: 0 | H22: 0 | I22: 4.7485969 | J22: 6.1985836 | K22: 0 | L22: 0 | M22: =SUM(E22:L22) | N22: 0.00029605748 | O22: 0 | P22: 0 | Q22: 0 | R22: 0 | S22: 0 | T22: 0 | U22: 0 | V22: 0 | W22: =SUM(O22:V22) | X22: 0
A23: 22 | B23: 30 | C23: 20 ก.ค. 2569 | D23: FALSE | E23: -24273.865 | F23: 76.79918 | G23: 3.8461538 | H23: 6.7041166 | I23: 4.7485969 | J23: 6.1985836 | K23: 0 | L23: 0 | M23: =SUM(E23:L23) | N23: -0.1141962 | O23: 0 | P23: 0 | Q23: 0 | R23: 0 | S23: 0 | T23: 0 | U23: 0 | V23: 0 | W23: =SUM(O23:V23) | X23: 0
... A29: 28 | B29: 30 | C29: 26 ก.ค. 2569 | D29: TRUE | E29: 0 | F29: 76.79918 | G29: 0 | H29: 0 | I29: 4.7485969 | J29: 6.1985836 | K29: 0 | L29: 0 | M29: =SUM(E29:L29) | N29: 0.00041448047 | O29: 0 | P29: 0 | Q29: 0 | R29: 0 | S29: 0 | T29: 0 | U29: 0 | V29: 0 | W29: =SUM(O29:V29) | X29: 0
B31: Config
B32: TodayDay (วันที่ปัจจุบัน 1-28) | C32: 11
B33: RevenueMonth (บาท) | C33: 5927657.1
B34: Incentive Target ประจำวัน (บาท) | C34: 26.368132
B35: Incentive Actual ประจำวัน (บาท) | C35: 162.43
B36: หมายเหตุ: เปลี่ยน TodayDay เพื่อเลื่อนวันที่ใช้คำนวณ Breakdown / KPI วันล่าสุด
